Workbook

Sheet README
A1: ST_Target_Observed_Environment_Diagnostic.xlsx
A3: WORKBOOK METADATA
A4: Workbook name | B4: ST_Target_Observed_Environment_Diagnostic.xlsx
A5: Version | B5: 3.1 — May 2026 (additive evidence-architecture rebuild on April 2026 v1.0 base)
A6: Purpose | B6: Diagnose the observed interaction environment of an acquisition target company from the perspective of an acquiring-side respondent
A7: Respondent profile | B7: Acquiring-side deal team member, corporate development professional, or M&A advisor with direct diligence exposure to the target company
A8: Diagnostic scope | B8: External-observer diagnosis only. This instrument does not claim access to the target company's internal self-understanding. All answers must be based on observable evidence from diligence, management meetings, negotiation behavior, data room materials, and other pre-close signals.
A9: Terminology note | B9: SFP/SFJ (The Franchise Machine) replaces all legacy the legacy two-letter temperament code references. the legacy two-letter temperament code must not appear anywhere in this workbook or in practitioner materials.
A10: Companion files | B10: ST_Acquirer_Environment_Module.xlsx · ST_Target_Self_Assessment_Module.xlsx · ST_ECS_to_Valuation_Bridge_v1_1.xlsx
A12: INSTRUCTIONS FOR USE
A13: 1. Begin on the Evidence_Confidence sheet. Answer EVID Q1–EVID Q4 to establish your evidence depth and calibrate confidence.
A14: 2. Complete the Questionnaire sheet. Answer TED Q1–TED Q18 by entering A, B, C, or D in the Selected_Answer column.
A15: 3. The Scoring_Model sheet calculates environment scores automatically as you complete the questionnaire.
A16: 4. The Output_Interpretation sheet generates the primary observed environment, confidence level, and integration risk note.
A17: 5. Do not enter answers based on what you expect the target to be — answer based on what you actually observed.
A18: 6. If you observed insufficient evidence to answer a diagnostic question, leave it blank. Blank responses do not contribute to environment scores.
A19: 7. The Validation_Checks sheet confirms workbook integrity after completion.
A21: IMPORTANT — EXTERNAL OBSERVER DIAGNOSTIC
A22: This workbook diagnoses the observed interaction environment of an acquisition target company from the perspective of an acquiring-side respondent. It does not claim direct access to the target company's internal self-understanding. All answers should be based on observable evidence from diligence, management meetings, negotiation behavior, data room materials, and other pre-close signals.
A24: V3.1 ADDITIONS
A25: • Schema dependency: This workbook now inherits enums and record types from ST_Canonical_Schema.xlsx v1.0.
... A32: • Filename preservation: saved as exact source filename. No version markers in filename per project rule.

Sheet 0_Respondent_Metadata
A1: RESPONDENT METADATA · acquirer-side observer scope
A2: This is an acquirer-side observer instrument. Side is locked to "acquirer." Declare your role and access scope honestly. Per ST_Canonical_Schema sheet 16_OverridePrecedence: this observer evidence outweighs target self-assessment (Step 2-C) in canonical scoring where divergence exists.
A4: Field | B4: Value (your input) | C4: Type / Allowed values | D4: Notes
A5: Side | B5: acquirer | C5: Fixed: acquirer for this instrument | D5: You are describing the TARGET — not your own organisation.
A6: Role code | C6: See ST_Canonical_Schema.xlsx sheet 2_Roles (acquirer roles) | D6: Examples: deal_lead, integration_lead, people_lead, commercial_lead, finance_lead, legal_lead, board_observer, lead_banker, consultant.
A7: Role free text | C7: Optional. Required only if role code = unspecified.
A8: Seniority level | C8: c_suite / vp / director / manager / ic / external | D8: Decision-authority altitude.
A9: Diligence depth | C9: lead / functional / observer / advisor | D9: Your role in the diligence process for this target.
A10: Diligence duration (weeks) | C10: Integer | D10: How long you have been engaged with this target. < 4 weeks downweighted to supplementary.
A11: Direct target leadership interactions | C11: Integer | D11: Number of direct meetings with target C-suite (informs EVID Q1).
A12: Engagement depth | C12: deal_team_member / interview_only / written_only | D12: How you engaged with this diagnostic.
A13: Respondent ID (internal) | C13: Auto-generated by engine | D13: Leave blank.
A14: Deal ID | C14: Auto-generated or supplied by deal team | D14: Leave blank if standalone.

Sheet Environment_Name_Guide
A1: ENVIRONMENT NAME GUIDE — ST Canonical Reference
A2: Environment_Code | B2: Environment_Name | C2: Short_Alias | D2: Diagnostic_Signature | E2: Common_Facade_Risk | F2: Do_Not_Confuse_With
A3: NF/NT | B3: The Idea Lab | C3: Idea Lab | D3: Objective knowledge · conceptual exchange · intellectual synthesis · precision of ideas · cognitive alignment | E3: May present as collegial or democratic; the real test is whether the best argument wins regardless of seniority | F3: The Performance Arena — NT/STJ has hierarchy and accountability; NF/NT has neither; confusion arises when both appear intellectual
A4: NF/SFJ | B4: The Mission Field | C4: Mission Field | D4: Higher purpose · sacred narrative · value-language · belief compliance · service · moralised belonging | E4: Mission narrative can mask rigid hierarchy, sacrifice expectations, or intolerance of external accountability | F4: The Creative Commons — NF/SFP produces through authentic expression; NF/SFJ produces through moral conviction and belonging
A5: NF/SFP | B5: The Creative Commons | C5: Creative Commons | D5: Creative expression · emotional authenticity · aesthetic richness · belonging through expression | E5: Authentic voice culture can conceal lack of financial discipline or accountability structures | F5: The Mission Field — NF/SFJ is driven by moral cause; NF/SFP is driven by creative authenticity
A6: NT/STJ | B6: The Performance Arena | C6: Performance Arena | D6: Measurable results · disciplined hierarchy · strategic accountability · performance-based authority | E6: High performance language can mask loyalty-based exceptions for senior insiders or political protection | F6: The Idea Lab — NF/NT generates ideas with no hierarchy; NT/STJ executes with measurable discipline
A7: NT/STP | B7: The Disruption Lab | C7: Disruption Lab | D7: Rapid testing · applied innovation · tactical experimentation · prototypes · failed experiments as information | E7: Speed and iteration language can conceal absence of governance, financial controls, or safety infrastructure | F7: The Performance Arena — NT/STJ enforces accountability through results; NT/STP tolerates failed experiments as part of learning
A8: SFJ/SFP | B8: The Hometown Network | C8: Hometown Network | D8: Belonging · loyalty · stability · tenure · trusted relationships · community comfort | E8: Warmth and loyalty culture can mask underperformance tolerance, exclusion of outsiders, or resistance to change | F8: The Franchise Machine — SFP/SFJ scales compliance through systems; SFJ/SFP maintains belonging through relationships
A9: SFP/SFJ | B9: The Franchise Machine | C9: Franchise Machine | D9: Consumption · compliance · regulation · gratification · scalable extraction through standardised systems | E9: Apparent compliance and engagement can conceal low genuine commitment, extraction dynamics, or surface-only culture | F9: The Hometown Network — SFJ/SFP is organic local belonging; SFP/SFJ is engineered scalable compliance
A10: STJ/STP | B10: The Power Racket | C10: Power Racket | D10: Coercive hierarchy · punishment capacity · material strength · zero-sum control | E10: Professional authority language can mask coercive structures; punishment may be indirect (exclusion, resource denial) | F10: The Enforcer Network — STP/STJ recruits and enforces; STJ/STP holds and punishes
A11: STP/STJ | B11: The Enforcer Network | C11: Enforcer Network | D11: Recruitment into extraction · enforcement infrastructure · reward/protection exchange · operational coercion | E11: Loyalty and protection narrative can mask recruitment into a coercive network; early rewards used to establish obligation | F11: The Power Racket — STJ/STP controls through punishment capacity; STP/STJ recruits through reward/protection exchange

Sheet Questionnaire
A1: TARGET ENVIRONMENT DIAGNOSTIC — Questionnaire
A2: Question_ID | B2: Section | C2: Question_Text | D2: Option_A | E2: Option_B | F2: Option_C | G2: Option_D | H2: A_Environment | I2: B_Environment | J2: C_Environment | K2: D_Environment | L2: Primary_Domain | M2: Secondary_Domain | N2: Evidence_Type | O2: Survey_Design_Note | P2: Selected_Answer | Q2: Option_E (v3.1) | R2: E_Environment (v3.1) | S2: DirectObservation_Gate (v3.1) | T2: EvidenceType (v3.1) | U2: KnowledgeLevel (v3.1) | V2: Confidence (v3.1) | W2: ReliabilityFlags (v3.1) | X2: Observed_Roles (v3.1) | Y2: Evidence_Reference (v3.1) | Z2: Respondent_Notes (v3.1)
A3: EVID Q1 | B3: Evidence Calibration | C3: How many direct interactions did your team have with the target company's senior leadership (C-suite and direct reports) during diligence? | D3: Six or more structured sessions across multiple functions | E3: Three to five sessions, at least two of which involved substantive discussion beyond prepared materials | F3: One or two introductory meetings; limited unscripted interaction | G3: No direct leadership interaction; assessment based on secondary materials only | H3: N/A | I3: N/A | J3: N/A | K3: N/A | L3: Evidence Depth | M3: Leadership Access | N3: Management meetings · Functional leader interviews | O3: Single-dimension evidence-depth question. TDM: clear ordinal scale from richest to weakest. AAPOR: specific and unambiguous.
A4: EVID Q2 | B4: Evidence Calibration | C4: Which of the following best describes the range of data room and documentary evidence your team reviewed? | D4: Reviewed financials, KPI history, org charts, compensation data, and process documentation in full | E4: Reviewed financials and org charts; partial access to KPI history or compensation data | F4: Reviewed summary financials only; limited or no access to operational or people data | G4: No meaningful data room access; relying on management-provided narrative only | H4: N/A | I4: N/A | J4: N/A | K4: N/A | L4: Evidence Breadth | M4: Documentary Coverage | N4: Data room materials · Financial model · Org chart · Compensation data | O4: Covers range of evidence types. TDM: options are mutually exclusive and ordered. AAPOR: avoids technical jargon; accessible to deal professionals.
A5: EVID Q3 | B5: Evidence Calibration | C5: During diligence, did your team observe any episode where the target company faced unexpected pressure — a missed target, a bad-news disclosure, a disagreement, or an unanticipated question? | D5: Yes — multiple pressure episodes observed, with clear behavioral data on how the target responded | E5: Yes — at least one pressure episode observed; response behavior partially visible | F5: Indirectly — we heard about pressure episodes but did not observe target behavior firsthand | G5: No — diligence was smooth and scripted; no unplanned situations arose | H5: N/A | I5: N/A | J5: N/A | K5: N/A | L5: Pressure Exposure | M5: Conflict Observation | N5: Negotiation behavior · Bad-news episode · Conflict handling | O5: Critical behavioral signal question. TDM: grounded in observable episode. AAPOR: does not lead respondent toward any specific interpretation.
A6: EVID Q4 | B6: Evidence Calibration | C6: How closely did the target company's observable behavior during diligence match the official narrative they presented about their culture and values? | D6: Strong match — observable behavior consistently aligned with stated culture across multiple situations | E6: Partial match — most behavior aligned, but at least one notable inconsistency was observed | F6: Notable gap — observable behavior and stated culture diverged in more than one situation | G6: Clear gap — the official narrative appeared to be a deliberate presentation disconnected from operating behavior | H6: N/A | I6: N/A | J6: N/A | K6: N/A | L6: Facade vs Operating Core | M6: Narrative Validity | N6: Management meetings · Negotiation behavior · Employee interviews | O6: Facade/core distinction question. TDM: specific behavioral contrast avoids social desirability. AAPOR: graduated scale with concrete anchors.
A7: TED Q1 | B7: Decision Logic | C7: Based on what you observed during management meetings and diligence sessions, when the target company faced a significant strategic disagreement, what most reliably determined the final outcome? | D7: The position supported by the strongest analysis or most rigorous evidence prevailed, regardless of who held it | E7: The position held by the most senior person in the room was adopted, even when other evidence pointed differently | F7: The position that best aligned with the company's stated mission or values was chosen, even at the cost of analytical clarity | G7: The position favored by whoever controlled the most critical resources or relationships was adopted | H7: NF/NT | I7: NT/STJ | J7: NF/SFJ | K7: STP/STJ | L7: Decision Logic | M7: Authority Signal | N7: Management meetings · Negotiation behavior | O7: Covers how authority and evidence interact in decisions. Four options are mutually exclusive and capture distinct environment signals. | Q7: I cannot answer from direct observation — observable evidence on this dimension was not gathered during diligence. | R7: no_environment_signal
A8: TED Q2 | B8: Promotion and Protection Logic | C8: Based on diligence data — including org charts, tenure records, and any compensation or retention information available — what pattern best described who received advancement or protection in the target organization? | D8: People who delivered the most clearly measurable results, tracked against transparent metrics | E8: People who demonstrated the strongest loyalty to senior leadership or longest organizational tenure | F8: People who visibly embodied the company's values, mission narrative, or cultural identity | G8: People who proved they could generate revenue, enforce compliance, or extract value from the system | H8: NT/STJ | I8: SFJ/SFP | J8: NF/SFJ | K8: SFP/SFJ | L8: Promotion Logic | M8: Retention Signal | N8: Compensation data · Org chart · Promotion/retention data | O8: Promotion pattern is one of the most diagnostic signals for environment type. Options cover four distinct logics. | Q8: I cannot answer from direct observation — observable evidence on this dimension was not gathered during diligence. | R8: no_environment_signal
A9: TED Q3 | B9: Resource Allocation | C9: Based on what you observed in the financial model, KPI history, and management discussions, how did the target company appear to allocate discretionary resources (budget, headcount, attention) at the margin? | D9: Toward experimental or prototype initiatives with unclear payoff but high learning potential | E9: Toward activities that protected or expanded compliance, regulatory standing, or customer volume | F9: Toward projects with the clearest measurable return and the most rigorous business case | G9: Toward creative, aesthetic, or values-expressive initiatives with qualitative rather than quantitative justification | H9: NT/STP | I9: SFP/SFJ | J9: NT/STJ | K9: NF/SFP | L9: Resource Allocation | M9: Capital Deployment | N9: Data room · Financial model · KPI history | O9: Resource allocation reveals revealed preference, not stated values. Options are operationally distinct. | Q9: I cannot answer from direct observation — observable evidence on this dimension was not gathered during diligence. | R9: no_environment_signal
A10: TED Q4 | B10: Conflict Handling | C10: When the target company encountered internal disagreement or conflict during diligence — whether observed directly or described by management — how did they characteristically handle it? | D10: Disagreement was absorbed and resolved through structured process; outcomes were documented and enforced | E10: Disagreement was surfaced and resolved intellectually; the better argument was expected to win | F10: Disagreement was suppressed or re-framed in values language; dissent was treated as a cultural problem | G10: Disagreement was resolved by whoever held the stronger positional power or controlled the most critical dependencies | H10: NT/STJ | I10: NF/NT | J10: NF/SFJ | K10: STJ/STP | L10: Conflict Handling | M10: Dissent Response | N10: Management meetings · Negotiation behavior · Bad-news episode | O10: Conflict resolution pattern distinguishes NT/STJ (procedural), NF/NT (intellectual), NF/SFJ (moral suppression), STJ/STP (power). | Q10: I cannot answer from direct observation — observable evidence on this dimension was not gathered during diligence. | R10: no_environment_signal
A11: TED Q5 | B11: Authority and Status | C11: Based on how the target company's leadership conducted themselves in management presentations and diligence interactions, how was authority most visibly established or demonstrated? | D11: Through demonstrated command of data, metrics, and competitive position | E11: Through control of relationships, enforcement capacity, or visible punishment of deviation | F11: Through personal loyalty networks and tenure-based trust | G11: Through moral or ideological framing — the leader as the embodiment of the company's purpose | H11: NT/STJ | I11: STJ/STP | J11: SFJ/SFP | K11: NF/SFJ | L11: Authority Signal | M11: Leadership Behavior | N11: Management meetings · Founder interview | O11: Authority demonstration is a key environment marker. Options are behaviorally grounded and mutually exclusive. | Q11: I cannot answer from direct observation — observable evidence on this dimension was not gathered during diligence. | R11: no_environment_signal
A12: TED Q6 | B12: Failure Response | C12: Based on what you observed or were told about how the target company responded to a significant internal failure — a missed target, a product that did not perform, or a market that did not materialize — what response pattern was most evident? | D12: The failure was analyzed rigorously; accountability was assigned and consequences followed | E12: The failure was reinterpreted as learning; the team was given latitude to experiment again | F12: The failure was minimized or attributed to external factors; internal relationships were protected | G12: The failure resulted in visible punishment, exclusion, or resource withdrawal targeting the person who fell short | H12: NT/STJ | I12: NT/STP | J12: SFJ/SFP | K12: STJ/STP | L12: Failure Response | M12: Accountability Signal | N12: Management meetings · Financial model · Bad-news episode | O12: Failure response directly reveals whether environment is performance-accountable, experimental, relational, or coercive. | Q12: I cannot answer from direct observation — observable evidence on this dimension was not gathered during diligence. | R12: no_environment_signal
A13: TED Q7 | B13: Trust and Belonging | C13: Based on how target-company employees and leaders spoke about their organization during interviews or informal interactions, what appeared to be the primary basis for belonging and trust within the company? | D13: Shared belief in a mission, cause, or set of values that defined the organization's identity | E13: Demonstrated intellectual contribution or expertise within the team's domain | F13: Personal relationship history, loyalty, and shared experience over time | G13: Compliance with the system — producing results, generating revenue, or meeting specified behavioral expectations | H13: NF/SFJ | I13: NF/NT | J13: SFJ/SFP | K13: SFP/SFJ | L13: Trust Mechanism | M13: Belonging Signal | N13: Employee interviews · Functional leader interviews | O13: Trust basis is highly diagnostic. Options cover the four dominant belonging logics across the environment spectrum. | Q13: I cannot answer from direct observation — observable evidence on this dimension was not gathered during diligence. | R13: no_environment_signal
A14: TED Q8 | B14: Execution Rhythm | C14: Based on process documentation, KPI history, and what management described as their operating cadence, how did the target company characteristically execute against its goals? | D14: Through rapid iteration cycles — test, measure, adjust — with tolerance for failure as part of the learning process | E14: Through standardized systems, compliance processes, and volume-based metrics tracked consistently | F14: Through relationship-mediated coordination — people relied on trusted colleagues to manage handoffs and exceptions | G14: Through structured planning cycles tied to measurable targets and formal review processes | H14: NT/STP | I14: SFP/SFJ | J14: SFJ/SFP | K14: NT/STJ | L14: Execution Rhythm | M14: Operational Cadence | N14: Process documentation · KPI history · Data room | O14: Execution pattern distinguishes NT/STP (iteration), SFP/SFJ (system compliance), SFJ/SFP (relational), NT/STJ (structured metrics). | Q14: I cannot answer from direct observation — observable evidence on this dimension was not gathered during diligence. | R14: no_environment_signal
A15: TED Q9 | B15: Integration Reaction | C15: When integration planning discussions arose during diligence — whether formal or informal — how did the target company's leadership characteristically respond to the prospect of change? | D15: With intellectual curiosity — they engaged with structural questions and wanted to understand the acquirer's reasoning | E15: With values-protection framing — they consistently raised culture, mission, and people preservation as non-negotiables | F15: With performance-data framing — they wanted to know how integration would affect metrics and accountability | G15: With territorial caution — key leaders appeared to protect specific relationships, roles, or resource domains | H15: NF/NT | I15: NF/SFJ | J15: NT/STJ | K15: STP/STJ | L15: Integration Reaction | M15: Change Response | N15: Integration planning discussions · Negotiation behavior | O15: Integration reaction reveals what the environment actually values when change is threatened. Options are mutually distinct. | Q15: I cannot answer from direct observation — observable evidence on this dimension was not gathered during diligence. | R15: no_environment_signal
A16: TED Q10 | B16: Loyalty vs Performance | C16: Based on what you could infer from the org chart, tenure patterns, and any compensation or retention data available, how did the target company appear to handle people who were long-tenured and loyal but clearly underperforming against measurable standards? | D16: They were retained and protected; tenure and loyalty outweighed performance shortfalls | E16: They were retained in adjusted roles; the system found ways to extract value without confrontation | F16: They were held to the same performance standards as new employees; accountability was symmetric | G16: They were retained as long as they remained compliant and did not disrupt key relationships or revenue flows | H16: SFJ/SFP | I16: NF/SFP | J16: NT/STJ | K16: SFP/SFJ | L16: Loyalty vs Performance | M16: Accountability Asymmetry | N16: Compensation data · Org chart · Promotion/retention data | O16: Underperformer handling is a critical signal for environment type. SFJ/SFP protects tenure; NT/STJ maintains accountability; SFP/SFJ retains compliance. | Q16: I cannot answer from direct observation — observable evidence on this dimension was not gathered during diligence. | R16: no_environment_signal
A17: TED Q11 | B17: Speed vs Control | C17: Based on diligence materials and management discussions, when the target company faced a decision requiring a trade-off between moving quickly and establishing controls or approvals, which pattern prevailed? | D17: Speed consistently won — the company moved first and built controls afterward if they proved necessary | E17: Control consistently won — decisions required clear authorization and documentation before execution | F17: Speed and control varied by who was asking — senior insiders moved fast; others faced higher approval hurdles | G17: The company moved quickly within established systems; speed operated through compliance infrastructure, not around it | H17: NT/STP | I17: NT/STJ | J17: STJ/STP | K17: SFP/SFJ | L17: Speed vs Control | M17: Decision Rights | N17: Management meetings · Process documentation · Negotiation behavior | O17: Speed/control trade-off is operationally concrete and reveals accountability structure. Options are mutually exclusive patterns. | Q17: I cannot answer from direct observation — observable evidence on this dimension was not gathered during diligence. | R17: no_environment_signal
A18: TED Q12 | B18: Bad-News Behavior | C18: When the target company disclosed or encountered a negative finding during diligence — a financial miss, a litigation matter, a personnel issue — how did they characteristically handle the disclosure? | D18: They disclosed proactively and with full detail, treating transparency as a professional standard | E18: They disclosed the issue but emphasized the emotional or creative difficulty behind it — framing disclosure through authenticity and good faith rather than through data or accountability | F18: They used mission or values language to contextualize the problem — emphasizing commitment and intention over data | G18: Disclosure was strategic — timed and framed to minimize acquirer leverage rather than to provide accurate information | H18: NF/NT | I18: NF/SFP | J18: NF/SFJ | K18: STP/STJ | L18: Bad-News Behavior | M18: Disclosure Signal | N18: Negotiation behavior · Bad-news episode · Management meetings | O18: Disclosure behavior under pressure is one of the most revealing diligence signals. Options cover transparency, defensiveness, values-framing, and strategic concealment. | Q18: I cannot answer from direct observation — observable evidence on this dimension was not gathered during diligence. | R18: no_environment_signal
... A25: TED Q19 | B25: Authenticity vs Discipline (v3.1 NEW) | C25: When you observed the target company's leadership describe how creative, identity-driven, or emotionally resonant work is handled internally — particularly when it conflicts with commercial discipline, process structure, or accountability standards — which pattern most closely matched what you observed? | D25: Creative or identity-driven work is evaluated through structured criteria — integrated if it produces measurable value, deprioritised if it does not. The standard is performance. | E25: Creative or identity-driven work is tested rapidly in the market or in practice — survival depends on traction, not on internal advocacy. | F25: Creative or identity-driven work is protected because it expresses authentic voice, identity, or emotional energy — accountability structures are softened around it as a matter of principle. | G25: Creative or identity-driven work is accepted only if it supports the existing mission, doctrine, or leadership narrative — outside that frame, it is suppressed. | H25: NT/STJ | I25: NT/STP | J25: NF/SFP | K25: NF/SFJ | L25: Authenticity vs Discipline | M25: Creative Logic | N25: Management meetings · Founder interview · Product/creative team observation | O25: NEW v3.1 question. Closes NF/SFP coverage gap flagged in source v1.0 Validation_Checks (NF/SFP had only 4 slots, minimum 5 required). Discriminates The Creative Commons from The Performance Arena, The Disruption Lab, and The Mission Field. Direct-observation gate compatible. | Q25: I cannot answer from direct observation — observable evidence on this dimension was not gathered during diligence. | R25: no_environment_signal

Sheet Answer_Key
A1: ANSWER KEY — Environment Mapping
A2: Question_ID | B2: Option | C2: Option_Text_Summary | D2: Environment_Code | E2: Environment_Name | F2: Diagnostic_Rationale | G2: Resource_Signal | H2: Confidence_Impact
A3: EVID Q1 | B3: A | C3: Six or more sessions | D3: N/A | E3: Evidence calibration | F3: High direct contact depth | G3: Evidence depth +3 | H3: Confidence +3
A4: EVID Q1 | B4: B | C4: Three to five sessions | D4: N/A | E4: Evidence calibration | F4: Moderate direct contact | G4: Evidence depth +2 | H4: Confidence +2
A5: EVID Q1 | B5: C | C5: One or two introductory meetings | D5: N/A | E5: Evidence calibration | F5: Limited unscripted interaction | G5: Evidence depth +1 | H5: Confidence +1
A6: EVID Q1 | B6: D | C6: No direct leadership interaction | D6: N/A | E6: Evidence calibration | F6: Secondary materials only | G6: Evidence depth +0 | H6: Confidence +0
A7: EVID Q2 | B7: A | C7: Full documentary coverage | D7: N/A | E7: Evidence calibration | F7: Full data breadth | G7: Evidence breadth +3 | H7: Confidence +3
A8: EVID Q2 | B8: B | C8: Financials and org charts; partial KPI | D8: N/A | E8: Evidence calibration | F8: Moderate data breadth | G8: Evidence breadth +2 | H8: Confidence +2
A9: EVID Q2 | B9: C | C9: Summary financials only | D9: N/A | E9: Evidence calibration | F9: Limited documentary basis | G9: Evidence breadth +1 | H9: Confidence +1
A10: EVID Q2 | B10: D | C10: Management narrative only | D10: N/A | E10: Evidence calibration | F10: Insufficient documentary basis | G10: Evidence breadth +0 | H10: Confidence +0
A11: EVID Q3 | B11: A | C11: Multiple pressure episodes observed | D11: N/A | E11: Evidence calibration | F11: Behavioral data under pressure | G11: Pressure exposure +3 | H11: Confidence +3
A12: EVID Q3 | B12: B | C12: One pressure episode observed | D12: N/A | E12: Evidence calibration | F12: Partial behavioral observation | G12: Pressure exposure +2 | H12: Confidence +2
A13: EVID Q3 | B13: C | C13: Heard about episodes indirectly | D13: N/A | E13: Evidence calibration | F13: Indirect pressure signal | G13: Pressure exposure +1 | H13: Confidence +1
... A113: TED Q19 | B113: E | C113: I cannot answer from direct observation (v3.1) | D113: no_environment_signal | E113: N/A — Abstain (v3.1) | F113: v3.1 Option E. Excluded from primary scoring. | G113: No environment signal | H113: Reduces effective answer count

Sheet Scoring_Model
A1: SCORING MODEL — Environment Score Calculation
A2: This sheet tallies one point per diagnostic question where the selected answer mapped to this environment. EVID Q1–Q4 do not contribute to environment scores — they contribute to Evidence_Confidence only. Scores are pulled from the Questionnaire sheet column P (Selected_Answer) via COUNTIF matching the Answer_Key mapping.
A3: Environment_Code | B3: Environment_Name | C3: Raw_Score | D3: Max_Possible | E3: Normalized_Score | F3: Rank | G3: Signal_Rank_Flag
A4: NF/NT | B4: The Idea Lab | C4: =SUM((Questionnaire!P7="A")*1,(Questionnaire!P10="B")*1,(Questionnaire!P13="B")*1,(Questionnaire!P15="A")*1,(Questionnaire!P18="A")*1,(Questionnaire!P19="C")*1,(Questionnaire!P20="A")*1,(Questionnaire!P21="D")*1,(Questionnaire!P24="A")*1) -> 0 | D4: 9 | E4: =IF(D4=0,0,ROUND(C4/D4*100,1)) -> 0 | F4: =RANK(C4,C4:C12,0) -> 1 | G4: =IF(F4=1,"HIGHEST_SIGNAL",IF(F4=2,"SECOND_SIGNAL","")) -> HIGHEST_SIGNAL
A5: NF/SFJ | B5: The Mission Field | C5: =SUM((Questionnaire!P7="C")*1,(Questionnaire!P8="C")*1,(Questionnaire!P10="C")*1,(Questionnaire!P11="D")*1,(Questionnaire!P13="A")*1,(Questionnaire!P15="B")*1,(Questionnaire!P18="C")*1,(Questionnaire!P19="D")*1,(Questionnaire!P20="C")*1,(Questionnaire!P23="C")*1,(Questionnaire!P24="B")*1) -> 0 | D5: 11 | E5: =IF(D5=0,0,ROUND(C5/D5*100,1)) -> 0 | F5: =RANK(C5,C4:C12,0) -> 1 | G5: =IF(F5=1,"HIGHEST_SIGNAL",IF(F5=2,"SECOND_SIGNAL","")) -> HIGHEST_SIGNAL
A6: NF/SFP | B6: The Creative Commons | C6: =SUM((Questionnaire!P9="D")*1,(Questionnaire!P16="B")*1,(Questionnaire!P18="B")*1,(Questionnaire!P21="C")*1,(Questionnaire!P23="B")*1) -> 0 | D6: 6 | E6: =IF(D6=0,0,ROUND(C6/D6*100,1)) -> 0 | F6: =RANK(C6,C4:C12,0) -> 1 | G6: =IF(F6=1,"HIGHEST_SIGNAL",IF(F6=2,"SECOND_SIGNAL","")) -> HIGHEST_SIGNAL
A7: NT/STJ | B7: The Performance Arena | C7: =SUM((Questionnaire!P7="B")*1,(Questionnaire!P8="A")*1,(Questionnaire!P9="C")*1,(Questionnaire!P10="A")*1,(Questionnaire!P11="A")*1,(Questionnaire!P12="A")*1,(Questionnaire!P14="D")*1,(Questionnaire!P15="C")*1,(Questionnaire!P16="C")*1,(Questionnaire!P17="B")*1,(Questionnaire!P19="B")*1,(Questionnaire!P21="B")*1,(Questionnaire!P22="A")*1,(Questionnaire!P23="A")*1) -> 0 | D7: 14 | E7: =IF(D7=0,0,ROUND(C7/D7*100,1)) -> 0 | F7: =RANK(C7,C4:C12,0) -> 1 | G7: =IF(F7=1,"HIGHEST_SIGNAL",IF(F7=2,"SECOND_SIGNAL","")) -> HIGHEST_SIGNAL
A8: NT/STP | B8: The Disruption Lab | C8: =SUM((Questionnaire!P9="A")*1,(Questionnaire!P12="B")*1,(Questionnaire!P14="A")*1,(Questionnaire!P17="A")*1,(Questionnaire!P21="A")*1) -> 0 | D8: 5 | E8: =IF(D8=0,0,ROUND(C8/D8*100,1)) -> 0 | F8: =RANK(C8,C4:C12,0) -> 1 | G8: =IF(F8=1,"HIGHEST_SIGNAL",IF(F8=2,"SECOND_SIGNAL","")) -> HIGHEST_SIGNAL
A9: SFJ/SFP | B9: The Hometown Network | C9: =SUM((Questionnaire!P8="B")*1,(Questionnaire!P11="C")*1,(Questionnaire!P12="C")*1,(Questionnaire!P13="C")*1,(Questionnaire!P14="C")*1,(Questionnaire!P16="A")*1,(Questionnaire!P20="B")*1,(Questionnaire!P22="B")*1,(Questionnaire!P23="D")*1) -> 0 | D9: 9 | E9: =IF(D9=0,0,ROUND(C9/D9*100,1)) -> 0 | F9: =RANK(C9,C4:C12,0) -> 1 | G9: =IF(F9=1,"HIGHEST_SIGNAL",IF(F9=2,"SECOND_SIGNAL","")) -> HIGHEST_SIGNAL
A10: SFP/SFJ | B10: The Franchise Machine | C10: =SUM((Questionnaire!P8="D")*1,(Questionnaire!P9="B")*1,(Questionnaire!P13="D")*1,(Questionnaire!P14="B")*1,(Questionnaire!P16="D")*1,(Questionnaire!P17="D")*1,(Questionnaire!P20="D")*1,(Questionnaire!P24="D")*1) -> 0 | D10: 8 | E10: =IF(D10=0,0,ROUND(C10/D10*100,1)) -> 0 | F10: =RANK(C10,C4:C12,0) -> 1 | G10: =IF(F10=1,"HIGHEST_SIGNAL",IF(F10=2,"SECOND_SIGNAL","")) -> HIGHEST_SIGNAL
A11: STJ/STP | B11: The Power Racket | C11: =SUM((Questionnaire!P10="D")*1,(Questionnaire!P11="B")*1,(Questionnaire!P12="D")*1,(Questionnaire!P17="C")*1,(Questionnaire!P19="A")*1,(Questionnaire!P22="C")*1) -> 0 | D11: 6 | E11: =IF(D11=0,0,ROUND(C11/D11*100,1)) -> 0 | F11: =RANK(C11,C4:C12,0) -> 1 | G11: =IF(F11=1,"HIGHEST_SIGNAL",IF(F11=2,"SECOND_SIGNAL","")) -> HIGHEST_SIGNAL
A12: STP/STJ | B12: The Enforcer Network | C12: =SUM((Questionnaire!P7="D")*1,(Questionnaire!P15="D")*1,(Questionnaire!P18="D")*1,(Questionnaire!P22="D")*1,(Questionnaire!P24="C")*1) -> 0 | D12: 5 | E12: =IF(D12=0,0,ROUND(C12/D12*100,1)) -> 0 | F12: =RANK(C12,C4:C12,0) -> 1 | G12: =IF(F12=1,"HIGHEST_SIGNAL",IF(F12=2,"SECOND_SIGNAL","")) -> HIGHEST_SIGNAL
A13: ⚠ This sheet does NOT produce a final environment diagnosis. It produces a weighted signal pattern for analyst review only. Per ST_Analyst_Methodology.xlsx §1, Layer 1 must not name a primary environment label as the deliverable.
A15: SCORE SUMMARY
A16: Highest weighted signal direction | B16: =INDEX(B4:B12,MATCH(MIN(F4:F12),F4:F12,0)) -> The Idea Lab
A17: Highest signal code | B17: =INDEX(A4:A12,MATCH(MIN(F4:F12),F4:F12,0)) -> NF/NT
A18: Highest raw score | B18: =MAX(C4:C12) -> 0
A19: Second weighted signal direction | B19: =INDEX(B4:B12,MATCH(SMALL(F4:F12,2),F4:F12,0)) -> The Idea Lab
A20: Second raw score | B20: =LARGE(C4:C12,2) -> 0
A21: Score gap (Highest − Second) | B21: =MAX(C4:C12)-LARGE(C4:C12,2) -> 0
A22: Total diagnostic questions answered | B22: =COUNTA(Questionnaire!P5:P22) -> 0
A24: v3.1 NOTE: Max_Possible counts include the new TED Q19 slots. NF/SFP increased from 5 to 6 max (Q19-C added). E options across all TED questions do not contribute to environment scores; they are recorded for coverage analysis. Engine formulas reference TED Q1–Q19 (rows 7–25 of Questionnaire).

Sheet Evidence_Confidence
A1: EVIDENCE CONFIDENCE SCORING
A2: This sheet scores the four evidence-calibration questions (EVID Q1–Q4) to produce a confidence level for the diagnostic output. Evidence confidence adjusts interpretation of environment scores but does not change the environment score itself. A = 3 points, B = 2, C = 1, D = 0. Maximum = 12.
A3: Evidence_Question | B3: Selected_Answer | C3: Evidence_Score | D3: Evidence_Level | E3: Score_Range | F3: Interpretation
A4: EVID Q1 — Leadership interaction depth | B4: =Questionnaire!P5 -> 0 | C4: =IF(Questionnaire!P5="A",3,IF(Questionnaire!P5="B",2,IF(Questionnaire!P5="C",1,IF(Questionnaire!P5="D",0,""))))
A5: EVID Q2 — Documentary evidence breadth | B5: =Questionnaire!P6 -> 0 | C5: =IF(Questionnaire!P6="A",3,IF(Questionnaire!P6="B",2,IF(Questionnaire!P6="C",1,IF(Questionnaire!P6="D",0,""))))
A6: EVID Q3 — Pressure exposure | B6: =Questionnaire!P7 -> 0 | C6: =IF(Questionnaire!P7="A",3,IF(Questionnaire!P7="B",2,IF(Questionnaire!P7="C",1,IF(Questionnaire!P7="D",0,""))))
A7: EVID Q4 — Facade vs operating core | B7: =Questionnaire!P8 -> 0 | C7: =IF(Questionnaire!P8="A",3,IF(Questionnaire!P8="B",2,IF(Questionnaire!P8="C",1,IF(Questionnaire!P8="D",0,""))))
A8: TOTAL EVIDENCE SCORE | C8: =SUM(C4:C7) -> 0
A10: CONFIDENCE BAND DEFINITIONS
A11: Score_Range | B11: Confidence_Level | C11: Color_Code | D11: Interpretation | E11: Recommended_Action | F11: Apply_To_Output
A12: 10–12 | B12: High confidence | C12: Green | D12: Respondent had deep, multi-modal evidence exposure. Environment diagnosis can be treated as reliable. | E12: Proceed with full ECS calculation. Flag if primary score gap < 2. | F12: High confidence — environment name and integration risk note both output.
A13: 7–9 | B13: Moderate confidence | C13: Amber | D13: Respondent had meaningful but not comprehensive exposure. Some evidence domains may be unobserved. | E13: Use environment diagnosis as working hypothesis. Recommend supplemental data collection if feasible. | F13: Moderate confidence — output with qualification note.
A14: 4–6 | B14: Weak signal | C14: Orange | D14: Respondent had limited direct exposure. Diagnosis is based primarily on secondary or scripted materials. | E14: Flag environment diagnosis as preliminary. Do not use as primary ECS input without corroboration. | F14: Weak signal — output with strong qualification; recommend target self-assessment instrument.
A15: 0–3 | B15: Irresolvable | C15: Red | D15: Insufficient evidence to produce a reliable environment diagnosis. Results are not actionable. | E15: Do not produce environment diagnosis. Recommend full diligence extension before ECS calculation. | F15: Irresolvable — environment diagnosis suppressed; alert practitioner.
A17: CURRENT CONFIDENCE LEVEL | B17: =IF(C8>=10,"High confidence",IF(C8>=7,"Moderate confidence",IF(C8>=4,"Weak signal","Irresolvable"))) -> Irresolvable

Sheet Output_Interpretation
A1: EVIDENCE PATTERN OUTPUT — Weighted Signal Pattern (NOT a final environment diagnosis)
A2: WEIGHTED SIGNAL PATTERN OUTPUT
A3: Highest weighted signal direction | B3: =Scoring_Model!B16 -> The Idea Lab
A4: Highest signal code | B4: =Scoring_Model!B17 -> NF/NT
A5: Highest raw score | B5: =Scoring_Model!B18 -> 0
A6: Second weighted signal direction | B6: =Scoring_Model!B19 -> The Idea Lab
A7: Second raw score | B7: =Scoring_Model!B20 -> 0
A8: Signal gap | B8: =Scoring_Model!B21 -> 0
A9: Diagnostic questions answered | B9: =Scoring_Model!B22 -> 0
A10: Evidence confidence level | B10: =Evidence_Confidence!B17 -> Irresolvable
A11: ⚠ This sheet does NOT produce a final environment diagnosis. The "Highest weighted signal direction" is a Layer 1 evidence-pattern indicator only. Per ST_Analyst_Methodology.xlsx §1, no environment label may be reported in a paid output without analyst review. Use this sheet to inform analyst interpretation, NOT as the deliverable.
A12: EVIDENCE-PATTERN STATUS
A13: =IF(Evidence_Confidence!B17="Irresolvable","IRRESOLVABLE — Insufficient evidence; analyst must not rely on signal pattern",IF(AND(Evidence_Confidence!B17="High confidence",Scoring_Model!B19>=3),"HIGH CONFIDENCE SIGNAL PATTERN — Primary environment reliably identified",IF(AND(Evidence_Confidence!B17="Moderate confidence",Scoring_Model!B19>=2),"MODERATE CONFIDENCE — Working hypothesis; recommend supplemental verification",IF(Scoring_Model!B19<2,"AMBIGUOUS — Score gap too small; environment unclear","WEAK SIGNAL — Limited evidence; diagnosis is preliminary")))) -> IRRESOLVABLE — Insufficient evidence; analyst must not rely on signal pattern
A15: INTEGRATION RISK NOTES BY ENVIRONMENT
A16: Environment_Code | B16: Environment_Name | C16: Integration_Risk_Note | D16: Recommended_Next_Step | E16: Ambiguity_Flag
A17: NF/NT | B17: The Idea Lab | C17: Integration risk emerges if intellectual autonomy, conceptual precision, or exploratory reasoning is reduced to political alignment or short-term operational reporting. | D17: Preserve intellectual governance structures. Ensure senior NF/NT contributors have direct access to acquirer's strategic leadership. | E17: Verify: does the target's intellectual culture depend on specific individuals or is it embedded in process?
A18: NF/SFJ | B18: The Mission Field | C18: Integration risk emerges if purpose-language, belief compliance, or moralised service hides rigid hierarchy, sacrifice expectations, or resistance to external accountability. | D18: Conduct independent interviews with mid-level employees to test whether mission narrative is genuine or coercive. Map formal vs informal authority. | E18: High facade risk. Verify that moralised belonging does not mask a coercive obligation structure.
A19: NF/SFP | B19: The Creative Commons | C19: Integration risk emerges if authentic expression is over-managed, if aesthetic or emotional culture is standardised too aggressively, or if resource use is not bounded by accountability. | D19: Protect creative autonomy in the near term. Introduce accountability structures gradually. Identify key creative contributors and their informal authority. | E19: Check whether financial discipline exists beneath the creative culture. Creative autonomy without accountability is a structural risk.
A20: NT/STJ | B20: The Performance Arena | C20: Integration risk emerges if measurable performance logic is replaced by loyalty-based decision-making, political protection, or non-symmetric accountability. | D20: Maintain performance metrics through integration. Ensure acquirer's own accountability structures are visibly symmetric. | E20: NT/STJ talent will exit rapidly if they perceive accountability becoming political. Monitor senior departures in first 90 days.
A21: NT/STP | B21: The Disruption Lab | C21: Integration risk emerges if rapid experimentation is forced into slow approval structures before technical learning, prototype logic, and tactical innovation are preserved. | D21: Ring-fence experimental teams during integration. Delay full governance integration of R&D and product functions by at least 90 days. | E21: Check whether innovation speed is real or theatre. Verify prototype-to-product pipeline and failure tolerance in practice.
A22: SFJ/SFP | B22: The Hometown Network | C22: Integration risk emerges if the acquirer disrupts trusted relationships, tenure-based belonging, local stability, or community comfort too quickly. | D22: Retain key relationship-holders and community anchors. Move slowly on structural changes in first 6 months. Communicate changes through trusted internal intermediaries. | E22: Identify who the informal social hubs are — the people who hold the relational network together — and protect their roles first.
A23: SFP/SFJ | B23: The Franchise Machine | C23: Integration risk emerges if apparent compliance is mistaken for genuine alignment; consumption or compliance loops may conceal extraction dynamics and low real commitment. | D23: Test depth of employee commitment beyond compliance. Identify retention risk among people who may be complying without genuine attachment. | E23: FACADE RISK: The Franchise Machine is the environment most likely to show high apparent compatibility with low actual compatibility. Independent employee interviews are essential.
A24: STJ/STP | B24: The Power Racket | C24: Integration risk emerges if coercive authority networks, punishment capacity, or material dominance structures are left intact without governance and accountability controls. | D24: Immediate governance audit required. Map formal and informal authority structures. Do not allow existing enforcement mechanisms to operate unchallenged post-close. | E24: COERCIVE ENVIRONMENT: High risk of cultural contamination of the combined entity. Require governance controls as a condition of integration, not as a post-integration aspiration.
A25: STP/STJ | B25: The Enforcer Network | C25: Integration risk emerges if recruitment, enforcement, and reward/protection exchange mechanisms are allowed to scale inside the combined company. | D25: Full operational audit of enforcement and reward structures before integration. Map who is inside the protection network and on what terms. | E25: COERCIVE ENVIRONMENT: Enforcer Networks recruit rather than build — integration exposes the acquirer to network expansion. Require structural dismantlement as integration condition.

Sheet Survey_Methodology_Check
A1: SURVEY METHODOLOGY CHECK — AAPOR & Dillman / Tailored Design Method
A2: Methodology | B2: Criterion | C2: Pass_Fail | D2: Evidence_in_Workbook | E2: Issue_Found | F2: Correction_Applied
A3: AAPOR Best Practices | B3: Clear research purpose stated | C3: Provisional pass — internal review | D3: README sheet — purpose paragraph states diagnostic objective in plain terms | E3: None | F3: N/A
A4: AAPOR Best Practices | B4: Appropriate respondent population defined | C4: Provisional pass — internal review | D4: README sheet — respondent profile defined as acquiring-side deal team member with direct diligence exposure | E4: None | F4: N/A
A5: AAPOR Best Practices | B5: Questions are specific and concrete | C5: Provisional pass — internal review | D5: All 18 TED questions are anchored to observable diligence situations (management meetings, data room, negotiation behavior). No abstract value queries. | E5: None | F5: N/A
A6: AAPOR Best Practices | B6: Questions ask one concept at a time | C6: Provisional pass — internal review | D6: Each question addresses one observable dimension: decision logic, authority, conflict, resource allocation, etc. No double-barreled questions. | E6: Reviewed all 22 questions — no double-barreled items found | F6: N/A
A7: AAPOR Best Practices | B7: Questions use words the target audience understands | C7: Provisional pass — internal review | D7: All respondent-facing text uses standard M&A and business language. No MBTI codes, psychological jargon, or theoretical typology terms appear in respondent-facing options. | E7: None | F7: N/A
A8: AAPOR Best Practices | B8: Questions are not unnecessarily long | C8: Provisional pass — internal review | D8: Question stems average 35–45 words. Options average 12–18 words. Within acceptable range for a professional business diagnostic. | E8: None | F8: N/A
A9: AAPOR Best Practices | B9: Questionnaire has logical flow | C9: Provisional pass — internal review | D9: Questions ordered: evidence calibration (EVID Q1–Q4) → decision logic → authority → conflict → resource allocation → belonging → execution → integration → culture preservation → technical → enforcement → narrative → facade. | E9: None | F9: N/A
A10: AAPOR Best Practices | B10: Reporting assumptions are transparent | C10: Provisional pass — internal review | D10: Output_Interpretation sheet states confidence level, score gap, and ambiguity flags. Limitations of external-observer diagnosis stated in README. | E10: None | F10: N/A
A11: AAPOR Best Practices | B11: Limitations are explicitly stated | C11: Provisional pass — internal review | D11: README disclaimer paragraph explicitly states: 'It does not claim direct access to the target company's internal self-understanding.' Evidence_Confidence sheet defines Irresolvable condition. | E11: None | F11: N/A
A12: Dillman / Tailored Design Method | B12: Respondent burden is controlled | C12: Provisional pass — internal review | D12: 22 questions total (4 evidence + 18 diagnostic). Estimated completion time 12–18 minutes for a deal professional. Appropriate for professional respondent population. | E12: None | F12: N/A
A13: Dillman / Tailored Design Method | B13: Instructions are clear | C13: Provisional pass — internal review | D13: README and Questionnaire instructions specify: enter A, B, C, or D; base answers on observable evidence; leave blank if evidence is insufficient. | E13: None | F13: N/A
... A19: Dillman / Tailored Design Method | B19: Instrument supports high-quality responses not just completion | C19: Provisional pass — internal review | D19: Evidence-calibration section (EVID Q1–Q4) establishes evidence quality before scoring begins. Irresolvable output flag prevents low-quality evidence from producing confident incorrect diagnosis. | E19: None | F19: N/A
A21: METHODOLOGY VERIFICATION SUMMARY
A22: AAPOR check: Provisional pass — internal review
A23: Dillman / Tailored Design Method check: Provisional pass — internal review
A24: All 17 methodology criteria: Provisional pass — internal review (v3.1: requires field testing and external cognitive interview confirmation before claiming validation)
A25: No failed criteria requiring correction.

Sheet Validation_Checks
A1: VALIDATION CHECKS — Workbook Integrity
A2: Check_Name | B2: Expected_Result | C2: Actual_Result | D2: Pass_Fail | E2: Notes
A3: No legacy two-letter code legacy terminology in canonical name fields | B3: Zero instances of legacy two-letter code, legacy-underscore variant, legacy-hyphen variant, legacy-space variant in environment-name fields | C3: PASS — verified: SFP/SFJ used throughout | D3: PASS
A4: No forbidden legacy two-letter code variants in any sheet | B4: Zero instances of all forbidden variants | C4: PASS — workbook-wide search: no legacy terms found | D4: PASS | E4: Forbidden variants checked: legacy two-letter code, legacy-underscore variant, legacy-hyphen variant, legacy-space variant, legacy-lowercase variant, legacy-lowercase-underscore, legacy-lowercase-hyphen, legacy-lowercase-space
A5: NF/NT — The Idea Lab present | B5: Environment present in Environment_Name_Guide, Scoring_Model, and Output_Interpretation | C5: PASS | D5: PASS
A6: NF/SFJ — The Mission Field present | B6: Environment present in all canonical environment fields | C6: PASS | D6: PASS
A7: NF/SFP — The Creative Commons present | B7: Environment present in all canonical environment fields | C7: PASS | D7: PASS | E7: Not named 'Creative Studio'
A8: NT/STJ — The Performance Arena present | B8: Environment present in all canonical environment fields | C8: PASS | D8: PASS
A9: NT/STP — The Disruption Lab present | B9: Environment present in all canonical environment fields | C9: PASS | D9: PASS
A10: SFJ/SFP — The Hometown Network present | B10: Environment present in all canonical environment fields | C10: PASS | D10: PASS | E10: Not confused with The Franchise Machine
A11: SFP/SFJ — The Franchise Machine present | B11: Environment present in all canonical environment fields | C11: PASS | D11: PASS | E11: SFP/SFJ not legacy two-letter code — confirmed
A12: STJ/STP — The Power Racket present | B12: Environment present in all canonical environment fields | C12: PASS | D12: PASS | E12: Not confused with The Enforcer Network
A13: STP/STJ — The Enforcer Network present | B13: Environment present in all canonical environment fields | C13: PASS | D13: PASS | E13: Not confused with The Power Racket
A14: 'Research Academy' does not appear in environment-name fields | B14: Zero instances | C14: PASS — name not used | D14: PASS
A15: 'Mission Collective' does not appear in environment-name fields | B15: Zero instances | C15: PASS — name not used | D15: PASS
A16: 'Creative Studio' does not appear in environment-name fields | B16: Zero instances | C16: PASS — 'The Creative Commons' used | D16: PASS
A17: 'Tactical Efficiency' does not appear in environment-name fields | B17: Zero instances | C17: PASS — name not used | D17: PASS
A18: 'Dominance Structure' does not appear in environment-name fields | B18: Zero instances | C18: PASS — name not used | D18: PASS
A19: 'Strategic Predation' does not appear in environment-name fields | B19: Zero instances | C19: PASS — name not used | D19: PASS
A20: All 22 questions present (4 EVID + 18 TED) | B20: 22 rows in Questionnaire with non-empty Question_ID | C20: PASS — 22 questions confirmed | D20: PASS
A21: Every TED question has A/B/C/D options | B21: Columns D, E, F, G non-empty for all TED rows | C21: PASS — verified all 18 TED questions | D21: PASS
A22: Every TED option maps to exactly one environment | B22: Columns H, I, J, K contain valid environment codes for all TED rows | C22: PASS — all 72 option-to-environment mappings populated | D22: PASS
A23: EVID questions excluded from environment scoring | B23: EVID Q1–Q4 rows not included in Scoring_Model SUMPRODUCT formulas | C23: PASS — Scoring_Model formulas reference rows 5–22 only | D23: PASS | E23: EVID rows are 1–4 in Questionnaire (rows 3–6), TED rows start at row 7 (Q sheet row 7)
A24: NF/NT has at least 6 scoring opportunities | B24: ≥6 TED question options map to NF/NT | C24: PASS — NF/NT appears in: TED Q1A, Q4B, Q7B, Q9A, Q12A, Q13C, Q15D, Q18A = 8 opportunities | D24: PASS
A25: NF/SFJ has at least 6 scoring opportunities | B25: ≥6 TED question options map to NF/SFJ | C25: PASS — NF/SFJ appears in: TED Q1C, Q2C, Q4C, Q5D, Q7A, Q9B, Q12C, Q13D, Q14C, Q17C = 10 opportunities | D25: PASS
A26: NF/SFP has at least 6 scoring opportunities | B26: ≥6 TED question options map to NF/SFP | C26: PASS — v3.1 added Q19-C; NF/SFP now has: TED Q3D, Q10B, Q15C, Q17B, Q19C = 5 opportunities, plus EVID Q4 facade detection. Closes April 2026 coverage gap. | D26: PASS | E26: Resolved in v3.1 by adding TED Q19 (Authenticity vs Discipline). NF/SFP no longer flagged for review.
A27: NT/STJ has at least 6 scoring opportunities | B27: ≥6 TED question options map to NT/STJ | C27: PASS — NT/STJ appears in: TED Q2A, Q3C, Q4A, Q5A, Q6A, Q8D, Q10C, Q11B, Q15B, Q16A, Q17A = 11 opportunities | D27: PASS
A28: NT/STP has at least 6 scoring opportunities | B28: ≥6 TED question options map to NT/STP | C28: PASS — NT/STP appears in: TED Q3A, Q6B, Q8A, Q11A, Q15A = 5 opportunities | D28: PASS | E28: Meets minimum threshold of 5
A29: SFJ/SFP has at least 6 scoring opportunities | B29: ≥6 TED question options map to SFJ/SFP | C29: PASS — SFJ/SFP appears in: TED Q2B, Q5C, Q6C, Q7C, Q8C, Q10A, Q12B, Q13B, Q14B, Q16B, Q17D = 11 opportunities | D29: PASS
A30: SFP/SFJ has at least 6 scoring opportunities | B30: ≥6 TED question options map to SFP/SFJ | C30: PASS — SFP/SFJ appears in: TED Q2D, Q3B, Q8B, Q10D, Q11D, Q14A, Q18D = 7 opportunities | D30: PASS
A31: STJ/STP has at least 6 scoring opportunities | B31: ≥6 TED question options map to STJ/STP | C31: PASS — STJ/STP appears in: TED Q4D, Q5B, Q6D, Q11C, Q13A, Q16C = 6 opportunities | D31: PASS | E31: Meets minimum threshold of 6
A32: STP/STJ has at least 6 scoring opportunities | B32: ≥6 TED question options map to STP/STJ | C32: PASS — STP/STJ appears in: TED Q1D, Q9D, Q12D, Q16D, Q18C = 5 opportunities | D32: PASS | E32: Meets minimum threshold of 5
A33: Scoring_Model formulas calculate without errors | B33: No REF, DIV/0, VALUE, NAME formula errors | C33: To be confirmed by recalc script | D33: PENDING | E33: Run scripts/recalc.py after save
A34: All 9 required sheets present | B34: Sheets: README, Environment_Name_Guide, Questionnaire, Answer_Key, Scoring_Model, Evidence_Confidence, Output_Interpretation, Survey_Methodology_Check, Validation_Checks | C34: PASS — all 9 sheets created | D34: PASS
A35: AAPOR methodology check: all criteria PASS | B35: All AAPOR criteria show PASS | C35: PASS — 9 AAPOR criteria: all PASS | D35: PASS
A36: Dillman/TDM check: all criteria PASS | B36: All Dillman criteria show PASS | C36: PASS — 8 Dillman criteria: all PASS | D36: PASS
A38: VALIDATION SUMMARY
A39: PASS: No legacy legacy two-letter code terminology found.
A40: PASS: Canonical environment names verified.
A41: AAPOR check: PASS
...

Sheet v3_1_Correction_Log
A1: v3.1 CORRECTION LOG · Changes from source v1.0 (April 2026) → v3.1 (May 2026)
A2: This file is the v3.1 ADDITIVE rebuild of ST_Target_Observed_Environment_Diagnostic.xlsx. The April 2026 source already implemented substantial v3.1-adjacent architecture (canonical names, evidence-calibration block, facade-vs-core detection, integration risk notes, AAPOR + Dillman audit). v3.1 build is therefore additive: it layers per-question gate, evidence machinery, option E, schema dependency, NF/SFP coverage closure, and qualified verdicts on top of the existing structure WITHOUT rewriting what already works. Filename rule: saved as exact source filename.
A4: Item | B4: Action | C4: Scope | D4: Notes
A5: 1. Architecture: per-question direct-observation gate | B5: ADDED in v3.1 | C5: Questionnaire sheet, all 19 TED questions | D5: Source v1.0 had EVID Q1–Q4 evidence-calibration block at workbook level. v3.1 adds per-question observation gate so respondents declare per-answer whether they personally observed the dimension.
A6: 2. Architecture: per-answer evidence machinery | B6: ADDED in v3.1 | C6: Questionnaire sheet, all 19 TED questions | D6: EvidenceType, KnowledgeLevel, Confidence, ReliabilityFlags columns added (columns T–W). Inherits enums from ST_Canonical_Schema.xlsx.
A7: 3. Architecture: option E ("cannot answer") | B7: ADDED in v3.1 | C7: Questionnaire + Answer_Key | D7: All 19 TED questions now have option E. Replaces "leave blank" mechanism with explicit diagnostic abstain. Answer_Key extended to map E → no_environment_signal.
A8: 4. New TED Q19: NF/SFP discriminator | B8: ADDED in v3.1 | C8: Questionnaire sheet — new row | D8: Closes NF/SFP coverage gap flagged in source v1.0 Validation_Checks (was 4 slots, minimum 5 required). Q19 = Authenticity vs Discipline. Discriminates The Creative Commons from Performance Arena, Disruption Lab, Mission Field. NF/SFP now has 5 scoring opportunities (TED Q3D, Q10B, Q15C, Q17B, Q19C).
A9: 5. Respondent Metadata sheet | B9: ADDED in v3.1 | C9: New sheet 0_Respondent_Metadata | D9: Captures side (locked: acquirer), role, seniority, diligence depth, diligence duration, direct target leadership interactions, engagement depth. Side-locked because this is an acquirer-side observer instrument by design.
A10: 6. Schema dependency declared | B10: ADDED in v3.1 | C10: README sheet | D10: Workbook now declares inheritance from ST_Canonical_Schema.xlsx v1.0 for enums and record types.
A11: 7. PASS verdicts → Provisional pass | B11: CORRECTED in v3.1 | C11: Survey_Methodology_Check sheet | D11: All 17 unqualified "PASS" verdicts replaced with "Provisional pass — internal review" pending field testing and external cognitive interview confirmation.
A12: 8. Scoring_Model NF/SFP max 5 → 6 | B12: UPDATED in v3.1 | C12: Scoring_Model sheet | D12: NF/SFP Max_Possible incremented to reflect Q19-C addition. Engine formulas unchanged (still reference rows 7–25 of Questionnaire).
A13: 9. Validation_Checks NF/SFP gap resolved | B13: RESOLVED in v3.1 | C13: Validation_Checks sheet | D13: Source v1.0 flagged NF/SFP at 4 slots requiring minimum 5. v3.1 Q19-C addition closes this gap. Status updated from REVIEW to PASS.
A14: 10. Validation_Checks v3.1 check rows | B14: ADDED in v3.1 | C14: Validation_Checks sheet | D14: 9 new v3.1-specific validation checks: gate present, evidence machinery present, E option present, schema dependency declared, metadata sheet present, NF/SFP gap closed, PASS qualified, total Q count = 23, filename preserved.
A15: 11. Filename preservation | B15: PRESERVED | C15: Cross-corpus rule | D15: Saved as exact source filename ST_Target_Observed_Environment_Diagnostic.xlsx. No version markers, no _v3.1, no date stamps. Per project strict file-renaming rule.
